Workbook

Sheet Sheet1
U2: Dates | V2: PX_HIGH | W2: PX_LOW | X2: PX_CLOSE_1D | Y2: PX_OPEN | Z2: st_dev | AA2: no_days | AB2: expiry
U4: 33240 | V4: 8.03 | W4: 7.79 | X4: 7.88 | Y4: 7.85 | Z4: 0.65708168 | AA4: 24 | AB4: 199103 | AC4: 1
U5: 33241 | V5: 8.55 | W5: 8.11 | X5: 8.5 | Y5: 8.14 | Z5: 0.65603811 | AA5: 25 | AB5: 199103 | AC5: =AC4+1
U6: 33242 | V6: 8.72 | W6: 8.3 | X6: 8.45 | Y6: 8.5 | Z6: 0.66955657 | AA6: 26 | AB6: 199103 | AC6: =AC5+1
U7: 33245 | V7: 8.24 | W7: 7.95 | X7: 8.03 | Y7: 8.24 | Z7: 0.70244288 | AA7: 27 | AB7: 199103 | AC7: =AC6+1
U8: 33246 | V8: 8.33 | W8: 7.89 | X8: 8.16 | Y8: 7.93 | Z8: 0.72476847 | AA8: 28 | AB8: 199103 | AC8: =AC7+1
N9: fibonacci | O9: price levels | U9: 33247 | V9: 8.8 | W9: 8.1 | X9: 8.65 | Y9: 8.14 | Z9: 0.72754656 | AA9: 29 | AB9: 199103 | AC9: =AC8+1
N10: 2 | O10: =$O$22+($M$16*N10) | Q10: upward extension | U10: 33248 | V10: 8.41 | W10: 8.13 | X10: 8.31 | Y10: 8.23 | Z10: 0.7399973 | AA10: 30 | AB10: 199103 | AC10: =AC9+1
N11: 1.764 | O11: =$O$22+($M$16*N11) | P11: =O10-O11 | U11: 33249 | V11: 8.65 | W11: 8.24 | X11: 8.36 | Y11: 8.32 | Z11: 0.75081334 | AA11: 31 | AB11: 199103 | AC11: =AC10+1
N12: 1.618 | O12: =$O$22+($M$16*N12) | P12: =O11-O12 | U12: 33252 | V12: 8.3 | W12: 7.71 | X12: 8.02 | Y12: 8.3 | Z12: 0.77334813 | AA12: 32 | AB12: 199103 | AC12: =AC11+1
N13: 1.5 | O13: =$O$22+($M$16*N13) | P13: =O12-O13 | U13: 33253 | V13: 8.2 | W13: 7.86 | X13: 8.15 | Y13: 8.15 | Z13: 0.78749645 | AA13: 33 | AB13: 199103 | AC13: =AC12+1
N14: 1.382 | O14: =$O$22+($M$16*N14) | P14: =O13-O14 | U14: 33254 | V14: 8.05 | W14: 7.85 | X14: 7.9 | Y14: 8.05 | Z14: 0.81267049 | AA14: 34 | AB14: 199103 | AC14: =AC13+1
K15: high | L15: low | M15: range | N15: 1.236 | O15: =$O$22+($M$16*N15) | P15: =O14-O15 | U15: 33255 | V15: 8.98 | W15: 8.44 | X15: 8.9 | Y15: 8.72 | Z15: 0.81127472 | AA15: 35 | AB15: 199103 | AC15: =AC14+1
J16: 136.28 | K16: 100 | L16: 0 | M16: =K16-L16 | N16: high | O16: =K16 | P16: =O15-O16 | Q16: fibonacci levels | U16: 33256 | V16: 8.95 | W16: 8.64 | X16: 8.93 | Y16: 8.64 | Z16: 0.80148654 | AA16: 36 | AB16: 199103 | AC16: =AC15+1
N17: 0.236 | O17: =$K$16-($M$16*N17) | P17: =O16-O17 | U17: 33259 | V17: 8.98 | W17: 8.71 | X17: 8.83 | Y17: 8.79 | Z17: 0.79228109 | AA17: 37 | AB17: 199103 | AC17: =AC16+1
N18: 0.382 | O18: =$K$16-($M$16*N18) | P18: =O17-O18 | U18: 33260 | V18: 8.83 | W18: 8.56 | X18: 8.77 | Y18: 8.73 | Z18: 0.76633913 | AA18: 38 | AB18: 199103 | AC18: =AC17+1
N19: 0.5 | O19: =$K$16-($M$16*N20) | P19: =O18-O19 | U19: 33261 | V19: 8.96 | W19: 8.62 | X19: 8.83 | Y19: 8.68 | Z19: 0.72783629 | AA19: 39 | AB19: 199103 | AC19: =AC18+1
N20: 0.618 | O20: =$K$16-($M$16*N21) | P20: =O19-O20 | U20: 33262 | V20: 9.58 | W20: 8.94 | X20: 9.57 | Y20: 8.94 | Z20: 0.66145673 | AA20: 40 | AB20: 199103 | AC20: =AC19+1
N21: 0.786 | O21: =$K$16-($M$16*N22) | P21: =O20-O21 | U21: 33263 | V21: 9.76 | W21: 9.45 | X21: 9.56 | Y21: 9.65 | Z21: 0.62412659 | AA21: 41 | AB21: 199103 | AC21: =AC20+1
N22: low | O22: =L16 | P22: =O21-O22 | U22: 33266 | V22: 9.49 | W22: 9.31 | X22: 9.38 | Y22: 9.44 | Z22: 0.59926677 | AA22: 42 | AB22: 199103 | AC22: =AC21+1
N23: 1.236 | O23: =$O$16-($M$16*N23) | P23: =O22-O23 | Q23: downward extension | U23: 33267 | V23: 9.82 | W23: 9.49 | X23: 9.71 | Y23: 9.49 | Z23: 0.59473748 | AA23: 43 | AB23: 199103 | AC23: =AC22+1
N24: 1.382 | O24: =$O$16-($M$16*N24) | P24: =O23-O24 | U24: 33268 | V24: 10.08 | W24: 9.73 | X24: 10.07 | Y24: 9.88 | Z24: 0.60773843 | AA24: 44 | AB24: 199103 | AC24: =AC23+1
N25: 1.5 | O25: =$O$16-($M$16*N25) | P25: =O24-O25 | U25: 33269 | V25: 10.2 | W25: 9.75 | X25: 10.07 | Y25: 10.05 | Z25: 0.66850156 | AA25: 45 | AB25: 199103 | AC25: =AC24+1
N26: 1.618 | O26: =$O$16-($M$16*N26) | P26: =O27-O28 | U26: 33270 | V26: 10.45 | W26: 9.95 | X26: 10.27 | Y26: 10.15 | Z26: 0.73029058 | AA26: 46 | AB26: 199103 | AC26: =AC25+1
N27: 1.764 | O27: =$O$16-($M$16*N27) | P27: =O28-O29 | U27: 33273 | V27: 10.4 | W27: 10.27 | X27: 10.32 | Y27: 10.33 | Z27: 0.78308641 | AA27: 47 | AB27: 199103 | AC27: =AC26+1
N28: 2 | O28: =$O$16-($M$16*N28) | P28: =O29-O30 | U28: 33274 | V28: 11.25 | W28: 10.38 | X28: 11.15 | Y28: 10.38 | Z28: 0.89051914 | AA28: 48 | AB28: 199103 | AC28: =AC27+1
N30: fibonacci | O30: price levels
N31: 2 | O31: =$L$37+($M$37*N31) | Q31: upward extension
N32: 1.764 | O32: =$L$37+($M$37*N32) | P32: =O31-O32
N33: 1.618 | O33: =$L$37+($M$37*N33) | P33: =O32-O33
N34: 1.5 | O34: =$L$37+($M$37*N34) | P34: =O33-O34
N35: 1.382 | O35: =$L$37+($M$37*N35) | P35: =O34-O35
K36: high | L36: low | M36: range | N36: 1.236 | O36: =$L$37+($M$37*N36) | P36: =O35-O36
J37: 136.28 | K37: 21073 | L37: 19152 | M37: =K37-L37 | N37: high | O37: =K37 | P37: =O36-O37 | Q37: fibonacci levels
N38: 0.236 | O38: =$K$37-($M$37*N38) | P38: =O37-O38
N39: 0.382 | O39: =$K$37-($M$37*N39) | P39: =O38-O39
N40: 0.5 | O40: =$K$37-($M$37*N40) | P40: =O39-O40
N41: 0.618 | O41: =$K$37-($M$37*N41) | P41: =O40-O41
N42: 0.786 | O42: =$K$37-($M$37*N42) | P42: =O41-O42
N43: low | O43: =L37 | P43: =O42-O43
...

Sheet Sheet3
A2: =Sheet1!N10 | B2: =Sheet1!O10 | C2: =Sheet1!P10 | D2: w | E2: =Sheet1!N31 | F2: =Sheet1!O31 | G2: =Sheet1!P31 | I2: =Sheet1!N52 | J2: =Sheet1!O52 | K2: =Sheet1!P52
A3: =Sheet1!N11 | B3: =Sheet1!O11 | C3: =Sheet1!P11 | D3: =D2 | E3: =Sheet1!N32 | F3: =Sheet1!O32 | G3: =Sheet1!P32 | I3: =Sheet1!N53 | J3: =Sheet1!O53 | K3: =Sheet1!P53
A4: =Sheet1!N12 | B4: =Sheet1!O12 | C4: =Sheet1!P12 | D4: =D3 | E4: =Sheet1!N33 | F4: =Sheet1!O33 | G4: =Sheet1!P33 | I4: =Sheet1!N54 | J4: =Sheet1!O54 | K4: =Sheet1!P54
A5: =Sheet1!N13 | B5: =Sheet1!O13 | C5: =Sheet1!P13 | D5: =D4 | E5: =Sheet1!N34 | F5: =Sheet1!O34 | G5: =Sheet1!P34 | I5: =Sheet1!N55 | J5: =Sheet1!O55 | K5: =Sheet1!P55
A6: =Sheet1!N14 | B6: =Sheet1!O14 | C6: =Sheet1!P14 | D6: =D5 | E6: =Sheet1!N35 | F6: =Sheet1!O35 | G6: =Sheet1!P35 | I6: =Sheet1!N56 | J6: =Sheet1!O56 | K6: =Sheet1!P56
A7: =Sheet1!N15 | B7: =Sheet1!O15 | C7: =Sheet1!P15 | D7: =D6 | E7: =Sheet1!N36 | F7: =Sheet1!O36 | G7: =Sheet1!P36 | I7: =Sheet1!N57 | J7: =Sheet1!O57 | K7: =Sheet1!P57
A8: =Sheet1!N16 | B8: =Sheet1!O16 | C8: =Sheet1!P16 | D8: =D7 | E8: =Sheet1!N37 | F8: =Sheet1!O37 | G8: =Sheet1!P37 | I8: =Sheet1!N58 | J8: =Sheet1!O58 | K8: =Sheet1!P58
A9: =Sheet1!N17 | B9: =Sheet1!O17 | C9: =Sheet1!P17 | D9: =D8 | E9: =Sheet1!N38 | F9: =Sheet1!O38 | G9: =Sheet1!P38 | I9: =Sheet1!N59 | J9: =Sheet1!O59 | K9: =Sheet1!P59
A10: =Sheet1!N18 | B10: =Sheet1!O18 | C10: =Sheet1!P18 | D10: =D9 | E10: =Sheet1!N39 | F10: =Sheet1!O39 | G10: =Sheet1!P39 | I10: =Sheet1!N60 | J10: =Sheet1!O60 | K10: =Sheet1!P60
A11: =Sheet1!N19 | B11: =Sheet1!O19 | C11: =Sheet1!P19 | D11: =D10 | E11: =Sheet1!N40 | F11: =Sheet1!O40 | G11: =Sheet1!P40 | I11: =Sheet1!N61 | J11: =Sheet1!O61 | K11: =Sheet1!P61
A12: =Sheet1!N20 | B12: =Sheet1!O20 | C12: =Sheet1!P20 | D12: =D11 | E12: =Sheet1!N41 | F12: =Sheet1!O41 | G12: =Sheet1!P41 | I12: =Sheet1!N62 | J12: =Sheet1!O62 | K12: =Sheet1!P62
A13: =Sheet1!N21 | B13: =Sheet1!O21 | C13: =Sheet1!P21 | D13: =D12 | E13: =Sheet1!N42 | F13: =Sheet1!O42 | G13: =Sheet1!P42 | I13: =Sheet1!N63 | J13: =Sheet1!O63 | K13: =Sheet1!P63
A14: =Sheet1!N22 | B14: =Sheet1!O22 | C14: =Sheet1!P22 | D14: =D13 | E14: =Sheet1!N43 | F14: =Sheet1!O43 | G14: =Sheet1!P43 | I14: =Sheet1!N64 | J14: =Sheet1!O64 | K14: =Sheet1!P64
... A20: =Sheet1!N28 | B20: =Sheet1!O28 | C20: =Sheet1!P28 | D20: =D19 | E20: =Sheet1!N49 | F20: =Sheet1!O49 | G20: =Sheet1!P49 | I20: =Sheet1!N70 | J20: =Sheet1!O70 | K20: =Sheet1!P70
A21: 2 | B21: 22994 | C21: 0 | D21: m
A22: 1.764 | B22: 22540.644 | C22: 453.356 | D22: m
A23: 1.618 | B23: 22260.178 | C23: 280.466 | D23: m
A24: 1.5 | B24: 22033.5 | C24: 226.678 | D24: m
A25: 1.382 | B25: 21806.822 | C25: 226.678 | D25: m
A26: 1.236 | B26: 21526.356 | C26: 280.466 | D26: m
A27: high | B27: 21073 | C27: 453.356 | D27: m
A28: 0.236 | B28: 20619.644 | C28: 453.356 | D28: m
A29: 0.382 | B29: 20339.178 | C29: 280.466 | D29: m
A30: 0.5 | B30: 20112.5 | C30: 226.678 | D30: m
A31: 0.618 | B31: 19885.822 | C31: 226.678 | D31: m
A32: 0.786 | B32: 19563.094 | C32: 322.728 | D32: m
A33: low | B33: 19152 | C33: 411.094 | D33: m
A34: 1.236 | B34: 18698.644 | C34: 453.356 | D34: m
A35: 1.382 | B35: 18418.178 | C35: 280.466 | D35: m
A36: 1.5 | B36: 18191.5 | C36: 226.678 | D36: m
A37: 1.618 | B37: 17964.822 | C37: 226.678 | D37: m
A38: 1.764 | B38: 17684.356 | C38: 280.466 | D38: m
A39: 2 | B39: 17231 | C39: 453.356 | D39: m
A40: 2 | B40: 25292 | C40: 0 | D40: q
A41: 1.764 | B41: 24567.48 | C41: 724.52 | D41: q
A42: 1.618 | B42: 24119.26 | C42: 448.22 | D42: q
A43: 1.5 | B43: 23757 | C43: 362.26 | D43: q
A44: 1.382 | B44: 23394.74 | C44: 362.26 | D44: q
A45: 1.236 | B45: 22946.52 | C45: 448.22 | D45: q
A46: high | B46: 22222 | C46: 724.52 | D46: q
...

Sheet Sheet2
A1: year | B1: closeType | C1: high | D1: low | E1: notes
A2: 2009 | B2: C>O | C2: at 50% no 2008 and closed at the highs | D2: broke low 2007 but did not reach -123,6% | E2: close=high, open then dipped further
A3: 2010 | B3: C>O | C3: just above 123.6% | D3: at the 76.4% | E3: chance to get it at 76.4%
A4: 2011 | B4: C>O | C4: 1.382 | D4: 38.2% (nearly 23.6%) | E4: open = close
A5: 2012 | B5: C=O | C5: 0.002
A6: 2013
A7: 2014
A8: 2015
A9: 2016
A10: 2017 | B10: C>O | D10: low=open, high=close | E10: low=open, high=close | F10: no pullback to buy | G10: similar pattern to 2019
A11: =A10+1 | B11: C<O | C11: 150% no 2017 | D11: 0.236 | E11: open/close far from h, l
A12: =A11+1 | B12: C>O | C12: 150% no 2018 | D12: 23.6% but equal to the open i didn't pull back | E12: low=open, high=close | F12: no pullback to buy | G12: similar pattern to 2017
A13: =A12+1 | B13: C>O | C13: 161.8% no 2019 | D13: -1.236 | E13: very long range from -123.6% to +161.8% | F13: mad year open then cleared all the body fibo and stopped around -123.6%
A14: =A13+1 | B14: C>O | C14: 161.8% no 2020 | D14: low=open, high=close | E14: low=open, high=close | F14: no pullback to buy | G14: similar pattern to 2017/19
A15: =A14+1 | B15: C<O | C15: high = open form 2021 | D15: off the lows but not by much | E15: open=high, close off the lows but not much | F15: wiped out 2021 completely but did not reach -123.6
A16: =A15+1 | B16: C>O | C16: high around high 2023 | D16: 23.6% but equal to the open i didn't pull back | F16: made back what's lost in 2022 ,no pullback to buy | G16: similar pattern to 2017/19/21
A17: =A16+1 | B17: C>O | C17: 223.6% really high | D17: around the open no pull back to 76.$% | E17: long range but positive no negative pullbacks | G17: similar pattern to 2017/19/21/23

Sheet Sheet4
A1: Date | B1: (R1) Open | C1: (R1) High | D1: (R1) Low | E1: (R1) Close | F1: (L | G1: Z-Score(14) (SPX) | H1: RSI (14) on Close (SPX) | I1: WLPR(14) (SPX) | J1: %DS(5) (SPX) | K1: Diff (SPX)
A2: 45733 | B2: 5903.26 | C2: 6147.43 | D2: 5504.65 | E2: 5675.12 | F2: 42149998592 | G2: 1.2729 | H2: 71.3092 | I2: -17.7838 | J2: 93.7317 | K2: 113.7521
A3: 45657 | B3: 5757.73 | C3: 6099.97 | D3: 5674 | E3: 5881.63 | F3: 48099999744 | G3: 1.7819 | H3: 75.4954 | I3: -8.3707 | J3: 90.5467 | K3: 129.6887
A4: 45565 | B4: 5471.08 | C4: 5767.37 | D4: 5119.26 | E4: 5762.48 | F4: 48440000512 | G4: 2.0301 | H4: 74.6996 | I4: -0.2149 | J4: 85.122 | K4: 114.6547
A5: 45471 | B5: 5257.97 | C5: 5523.64 | D5: 4953.56 | E5: 5460.48 | F5: 45680001024 | G5: 2.0616 | H5: 72.606 | I5: -3.1082 | J5: 79.5163 | K5: 85.0953
A6: 45380 | B6: 4745.2 | C6: 5264.85 | D6: 4682.11 | E6: 5254.35 | F6: 44180000768 | G6: 2.1984 | H6: 71.0898 | I6: -0.517 | J6: 74.5878 | K6: 53.8682
A7: 45289 | B7: 4284.52 | C7: 4793.3 | D7: 4103.78 | E7: 4769.83 | F7: 43050000384 | G7: 1.5404 | H7: 67.1173 | I7: -2.8408 | J7: 71.6784 | K7: 13.14
A8: 45198 | B8: 4450.48 | C8: 4607.07 | D8: 4238.63 | E8: 4288.05 | F8: 39530000384 | G8: 0.6126 | H8: 62.3391 | I8: -22.3763 | J8: 71.3501 | K8: -10.7994
A9: 45107 | B9: 4102.2 | C9: 4458.48 | D9: 4048.28 | E9: 4450.38 | F9: 42319998976 | G9: 0.9773 | H9: 65.3082 | I9: -14.0188 | J9: 74.6938 | K9: -6.1818
A10: 45016 | B10: 3853.29 | C10: 4195.44 | D10: 3794.33 | E10: 4109.31 | F10: 44269998080 | G10: 0.5343 | H10: 61.7543 | I10: -27.0032 | J10: 80.3335 | K10: -22.0105
A11: 44925 | B11: 3609.78 | C11: 4100.96 | D11: 3491.58 | E11: 3839.5 | F11: 43910000640 | G11: 0.1956 | H11: 58.6421 | I11: -37.2748 | J11: 86.2817 | K11: -17.9037
A12: 44834 | B12: 3781 | C12: 4325.28 | D12: 3584.13 | E12: 3585.62 | F12: 40699998208 | G12: -0.1123 | H12: 55.4765 | I12: -46.94 | J12: 90.774 | K12: 10.3301
A13: 44742 | B13: 4540.32 | C13: 4593.45 | D13: 3636.87 | E13: 3785.38 | F13: 44459999232 | G13: 0.2715 | H13: 58.7627 | I13: -39.3352 | J13: 93.8089 | K13: 73.0091
... A62: 40268 | B62: 1116.56 | C62: 1180.69 | D62: 1044.5 | E62: 1169.43 | F62: 60400001024 | G62: -0.2162 | H62: 53.425 | I62: -44.7223 | J62: 32.0237 | K62: -33.7002
A63: 40178 | B63: 1054.91 | C63: 1130.38 | D63: 1019.95 | E63: 1115.1 | F63: 63840002048 | G63: -0.5008 | H63: 50.9429 | I63: -50.6972 | K63: -47.5379
A64: 40086 | B64: 920.82 | C64: 1080.15 | D64: 869.32 | E64: 1057.08 | F64: 69819998208 | G64: -0.8065 | H64: 48.2056 | I64: -57.078 | K64: -60.4143
A65: 39994 | B65: 793.59 | C65: 956.23 | D65: 783.32 | E65: 919.32 | F65: 79109996544 | G65: -1.5178 | H65: 40.9402 | I65: -72.2281 | K65: -70.4773
A66: 39903 | B66: 902.99 | C66: 943.85 | D66: 666.79 | E66: 797.87 | F66: 86980001792 | G66: -2.3844 | H66: 33.2783 | I66: -85.5845 | K66: -67.3105
A67: 39813 | B67: 1164.17 | C67: 1167.03 | D67: 741.02 | E67: 903.25 | F67: 86670000128 | G67: -2.6583 | H67: 37.1627 | I67: -80.5729 | K67: -45.2182
A68: 39721 | B68: 1276.69 | C68: 1313.15 | D68: 1106.39 | E68: 1166.36 | F68: 79700000768 | G68: -1.5035 | H68: 50.9512 | I68: -87.2323 | K68: -18.1188
A69: 39629 | B69: 1326.41 | C69: 1440.24 | D69: 1272 | E69: 1280 | F69: 72749998080 | G69: -0.5 | H69: 59.8584 | I69: -67.3024 | K69: -1.5216
A70: 39538 | B70: 1467.97 | C70: 1471.77 | D70: 1256.98 | E70: 1322.7 | F70: 93350002688 | G70: -0.0655 | H70: 63.7467 | I70: -52.1486 | K70: 12.0844
A71: 39447 | B71: 1527.29 | C71: 1576.09 | D71: 1406.1 | E71: 1468.36 | F71: 77269999616 | G71: 1.2086 | H71: 80.2613 | I71: -20.9034 | K71: 26.9978
A72: 39353 | B72: 1504.66 | C72: 1555.9 | D72: 1370.6 | E72: 1526.75 | F72: 86480003072 | G72: 1.857 | H72: 88.8271 | I72: -5.8868 | K72: 32.3105
A73: 39262 | B73: 1420.83 | C73: 1540.56 | D73: 1416.37 | E73: 1503.35 | F73: 81439997952 | G73: 2.0897 | H73: 88.3651 | I73: -7.7547 | K73: 30.8452
A74: 39171 | B74: 1418.03 | C74: 1461.57 | D74: 1363.98 | E74: 1420.86 | F74: 80099999744 | G74: 1.8614 | H74: 86.5433 | I74: -8.7435 | K74: 27.1336
A75: 39080 | B75: 1335.82 | C75: 1431.81 | D75: 1327.1 | E75: 1418.3 | F75: 76940001280 | G75: 2.0674 | H75: 86.4823 | I75: -2.8685 | K75: 26.2772
A76: 38989 | B76: 1270.06 | C76: 1340.28 | D76: 1224.54 | E76: 1335.85 | F76: 82600001536 | G76: 1.6108 | I76: -0.8996 | K76: 22.0081
A77: 38898 | B77: 1302.88 | C77: 1326.7 | D77: 1219.29 | E77: 1270.2 | F77: 100069998592.00 | K77: 20.8811
A78: 38807 | B78: 1248.29 | C78: 1310.88 | D78: 1245.74 | E78: 1294.83 | F78: 95440003072 | K78: 23.2308
A79: 38716 | B79: 1228.81 | C79: 1275.8 | D79: 1168.2 | E79: 1248.29 | F79: 81790001152 | K79: 21.8149
A80: 38625 | B80: 1191.33 | C80: 1245.86 | D80: 1183.55 | E80: 1228.81 | F80: 76330000384 | K80: 21.8403
A81: 38533 | B81: 1180.59 | C81: 1219.59 | D81: 1136.15 | E81: 1191.33 | F81: 80829997056 | K81: 21.4872
A82: 38442 | B82: 1211.92 | C82: 1229.11 | D82: 1163.69 | E82: 1180.59 | F82: 81390002176 | K82: 22.472
A83: 38352 | B83: 1114.58 | C83: 1217.33 | D83: 1090.19 | E83: 1211.92 | F83: 78949998592 | K83: 22.8644
A84: 38260 | B84: 1140.84 | C84: 1140.84 | D84: 1060.72 | E84: 1114.58 | F84: 67229999104 | K84: 18.0772
A85: 38168 | B85: 1126.21 | C85: 1150.57 | D85: 1076.32 | E85: 1140.84 | F85: 68130000896 | K85: 18.6106
A86: 38077 | B86: 1111.92 | C86: 1163.23 | D86: 1087.06 | E86: 1126.21 | F86: 76030001152 | K86: 15.0692
A87: 37986 | B87: 995.97 | C87: 1112.56 | D87: 995.97 | E87: 1111.92 | F87: 71639998464 | K87: 9.5537
A88: 37894 | B88: 974.5 | C88: 1040.29 | D88: 960.84 | E88: 995.97 | F88: 76009996288 | K88: 1.3702
...

Sheet stopLoss
A1: buy signal | C1: unit to buy | D1: stop loss for unit bought @ 23.6% | E1: stop loss for unit bought @38.2% | F1: stop loss for unit bought @ 61.8% | G1: stop loss for unit bought @ 76.4%
A2: main bucket | B2: sub-bucket
A3: 0 | B3: =A3
B4: =A9
B5: =A15
B6: =A21
B7: =A27
B8: =A33
A9: 0.236 | B9: =B3 | C9: 1
B10: =B4
B11: =B5
B12: =B6
B13: =B7
B14: =B8
A15: 0.382 | B15: =B9 | C15: 2
B16: =B10
B17: =B11
B18: =B12
B19: =B13
B20: =B14
A21: 0.5 | B21: =B15
B22: =B16 | D22: -1 | E22: -1
B23: =B17
B24: =B18
B25: =B19
B26: =B20
A27: 0.618 | B27: =B21 | C27: 2
B28: =B22 | E28: -1
B29: =B23
B30: =B24
B31: =B25
B32: =B26
A33: 0.764 | B33: =B27 | C33: 1
B34: =B28
B35: =B29
B36: =B30
B37: =B31
B38: =B32
B39: =B33
B40: =B34 | F40: -2
...

Sheet takeProfit
A1: buy signal | C1: unit to buy | D1: take profit for unit bought @ 23.6% | E1: take profit for unit bought @38.2% | F1: take profit for unit bought @ 61.8% | G1: stop loss for unit bought @ 76.4%
A2: main bucket | B2: sub-bucket | I2: 2.618 | J2: 361.8
A3: 2.618 | I3: 2 | J3: 300
A4: 2 | I4: 1.618 | J4: 261.8
A5: 1.618 | I5: 1.382 | J5: 238.2
A6: 1.382 | D6: -1 | I6: 1 | J6: 200
A7: 1 | I7: 0.618 | J7: 161.8
A8: 0.618 | I8: 0.5 | J8: 150
A9: 0.5 | I9: 0.382 | J9: 138.2
A10: 0.382 | I10: 0.236 | J10: 123.6
A11: 0.236 | E11: -1
A12: 0 | B12: =A12 | E12: -1
B13: =A18
B14: =A24
B15: =A30
B16: =A36
B17: =A42
A18: 0.236 | B18: =B12 | C18: 1 | F18: -1
B19: =B13
B20: =B14
B21: =B15
B22: =B16
B23: =B17
A24: 0.382 | B24: =B18 | C24: 2 | F24: -1
B25: =B19
B26: =B20
B27: =B21
B28: =B22
B29: =B23
A30: 0.5 | B30: =B24 | G30: -1
B31: =B25
B32: =B26
B33: =B27
B34: =B28
B35: =B29
A36: 0.618 | B36: =B30 | C36: 2
B37: =B31
B38: =B32
B39: =B33
B40: =B34
...
